Workbook

Sheet Cover
B2: Anadarko Petroleum Corp. (APC) - Cover
B4: Formatting
B5: Colors
B6: Formulas | C6: =0, 0, 0, 1 -> 0, 0, 0, 1
B7: Hard Codes | C7: =0, 0, 255, 1 -> 0, 0, 255, 1
B8: Link to Different Cell in Same Sheet | C8: =112, 48, 160, 1 -> 112, 48, 160, 1
B9: Link to Different Cell in Different Sheet | C9: =0, 176, 80, 1 -> 0, 176, 80, 1
B11: Team - Group 20
B12: Brianna Lin
B13: Cindy Chen
B14: Evelyn Nguyen
B15: Hannah Yeom
B16: Jean Lin

Sheet DCF
F1: Year | G1: 2017 | H1: =+G1+1 | I1: =+H1+1 | J1: =+I1+1 | K1: =+J1+1 | L1: =+K1+1 | M1: =+L1+1 | N1: =+M1+1 | O1: =+N1+1 | ... R1: =+Q1+1
B2: Anadarko Petroleum Corp. (APC) - Discounted Cashflow Analysis Model | F2: Period | I2: 0 | J2: =I2+1 | K2: =J2+1 | L2: =K2+1 | M2: =L2+1 | N2: =M2+1 | O2: =N2+1 | P2: =O2+1 | Q2: =P2+1 | R2: =Q2+1
B3: Value of Andarko on December 31, 2018
B5: APC - Control | E5: APC - Discounted Cashflow Analysis Valuation | T5: APC - Sensitivity Analysis
B7: Cashflow Assumptions | E7: Forecast | T7: Step | U7: 0.005
B8: Effective Tax Rate | C8: =WACC!C17 | E8: ($ in millions) | G8: =TEXT(G$1,"#")&"A" | H8: =TEXT(H$1,"#")&"A" | I8: =TEXT(I$1,"#")&"E" | J8: =TEXT(J$1,"#")&"P" | K8: =TEXT(K$1,"#")&"P" | L8: =TEXT(L$1,"#")&"P" | M8: =TEXT(M$1,"#")&"P" | N8: =TEXT(N$1,"#")&"P" | O8: =TEXT(O$1,"#")&"P" | P8: =TEXT(P$1,"#")&"P" | Q8: =TEXT(Q$1,"#")&"P" | R8: =TEXT(R$1,"#")&"P" | V8: WACC
B9: WACC | C9: =WACC!C22 | E9: Total Revenue | G9: =INDEX('Exhibit 1'!B:B,MATCH("Total revenue, net",'Exhibit 1'!A:A,0)) | H9: ='Exhibit 1'!C10 | I9: ='Exhibit 4a'!D7 | J9: ='Exhibit 4a'!E7 | K9: ='Exhibit 4a'!F7 | L9: ='Exhibit 4a'!G7 | M9: ='Exhibit 4a'!H7 | N9: ='Exhibit 4a'!I7 | O9: ='Exhibit 4a'!J7 | P9: ='Exhibit 4a'!K7 | ... R9: ='Exhibit 4a'!M7 | U9: =R31 | V9: =W9-$U$7 | W9: =X9-$U$7 | X9: 0.086969172 | Y9: =X9+$U$7 | Z9: =Y9+$U$7
B10: Terminal Value Growth Rate | C10: =+'Exhibit 5'!C10 | E10: % YoY Growth | H10: =(H9-G9)/G9 | I10: =(I9-H9)/H9 | J10: =(J9-I9)/I9 | K10: =(K9-J9)/J9 | L10: =(L9-K9)/K9 | M10: =(M9-L9)/L9 | N10: =(N9-M9)/M9 | O10: =(O9-N9)/N9 | ... R10: =(R9-Q9)/Q9 | T10: Terminal Growth Rate | U10: =U11-$U$7 | W10: 50321.92 | X10: 46558.151 | Y10: 43255.398 | Z10: 40335.586
U11: =U12-$U$7 | V11: 57681.872 | W11: 52850.662 | X11: 48686.697 | Y11: 45062.859 | Z11: 41882.316
E12: EBITDAX | G12: ='Exhibit 1'!B21+'Exhibit 1'!B14+'Exhibit 1'!B17 | H12: ='Exhibit 1'!C21+'Exhibit 1'!C14+'Exhibit 1'!C17 | I12: ='Exhibit 4a'!D8 | J12: ='Exhibit 4a'!E8 | K12: ='Exhibit 4a'!F8 | L12: ='Exhibit 4a'!G8 | M12: ='Exhibit 4a'!H8 | N12: ='Exhibit 4a'!I8 | O12: ='Exhibit 4a'!J8 | P12: ='Exhibit 4a'!K8 | ... R12: ='Exhibit 4a'!M8 | U12: 0.018 | V12: 61230.884 | W12: 55774.71 | X12: 51123.867 | Y12: 47114.673 | Z12: 43624.912
E13: (-) D&A | G13: ='Exhibit 1'!B17*-1 | H13: ='Exhibit 1'!C17*-1 | I13: =-'Exhibit 4a'!D10 | J13: =-'Exhibit 4a'!E10 | K13: =-'Exhibit 4a'!F10 | L13: =-'Exhibit 4a'!G10 | M13: =-'Exhibit 4a'!H10 | N13: =-'Exhibit 4a'!I10 | O13: =-'Exhibit 4a'!J10 | P13: =-'Exhibit 4a'!K10 | ... R13: =-'Exhibit 4a'!M10 | U13: =U12+$U$7 | V13: 65437.496 | W13: 59194.619 | X13: 53942.028 | Y13: 49463.984 | Z13: 45603.091
E14: (-) Exploration | G14: ='Exhibit 1'!B14*-1 | H14: ='Exhibit 1'!C14*-1 | I14: =I15*I9*-1 | J14: =J15*J9*-1 | K14: =K15*K9*-1 | L14: =L15*L9*-1 | M14: =M15*M9*-1 | N14: =N15*N9*-1 | O14: =O15*O9*-1 | P14: =P15*P9*-1 | ... R14: =R15*R9*-1 | U14: =U13+$U$7 | V14: 70503.14 | W14: 63248.206 | X14: 57238.093 | Y14: 52180.552 | Z14: 47868.091
E15: % of Revenue | G15: =G14/G9*-1 | H15: =H14/H9*-1 | I15: =AVERAGE($F$15:$H$15) | J15: =+I15 | K15: =+J15 | L15: =+K15 | M15: =+L15 | N15: =+M15 | O15: =+N15 | P15: =+O15 | Q15: =+P15 | R15: =+Q15
E17: EBIT | G17: =SUM(G12:G14) | H17: =SUM(H12:H14) | I17: =I12+I13+I14 | J17: =J12+J13+J14 | K17: =K12+K13+K14 | L17: =L12+L13+L14 | M17: =M12+M13+M14 | N17: =N12+N13+N14 | O17: =O12+O13+O14 | P17: =P12+P13+P14 | ... R17: =R12+R13+R14
E18: (-) Tax Benefit/(Expense) | G18: =-G17*$C$8 | H18: =-H17*$C$8 | I18: =-I17*$C$8 | J18: =-J17*$C$8 | K18: =-K17*$C$8 | L18: =-L17*$C$8 | M18: =-M17*$C$8 | N18: =-N17*$C$8 | ... R18: =-R17*$C$8
E19: EBIAT | G19: =G17+G18 | H19: =H17+H18 | I19: =I17+I18 | J19: =J17+J18 | K19: =K17+K18 | L19: =L17+L18 | M19: =M17+M18 | N19: =N17+N18 | ... R19: =R17+R18
E20: (+) D&A | G20: ='Exhibit 1'!B17 | H20: ='Exhibit 1'!C17 | I20: ='Exhibit 4a'!D10 | J20: ='Exhibit 4a'!E10 | K20: ='Exhibit 4a'!F10 | L20: ='Exhibit 4a'!G10 | M20: ='Exhibit 4a'!H10 | N20: ='Exhibit 4a'!I10 | O20: ='Exhibit 4a'!J10 | P20: ='Exhibit 4a'!K10 | ... R20: ='Exhibit 4a'!M10
E22: Cash Flow from Operations | G22: =G19+G20 | H22: =H19+H20 | I22: =I19+I20 | J22: =J19+J20 | K22: =K19+K20 | L22: =L19+L20 | M22: =M19+M20 | N22: =N19+N20 | ... R22: =R19+R20
E23: (-) CapEx | I23: =-'Exhibit 4a'!D9 | J23: =-'Exhibit 4a'!E9 | K23: =-'Exhibit 4a'!F9 | L23: =-'Exhibit 4a'!G9 | M23: =-'Exhibit 4a'!H9 | N23: =-'Exhibit 4a'!I9 | O23: =-'Exhibit 4a'!J9 | P23: =-'Exhibit 4a'!K9 | ... R23: =-'Exhibit 4a'!M9
E24: (-) Change in NWC | H24: =(('Exhibit 2'!C13-'Exhibit 2'!C9-'Exhibit 2'!C23)-('Exhibit 2'!B13-'Exhibit 2'!B9-'Exhibit 2'!B23))*-1 | I24: =I25*I9 | J24: =J25*J9 | K24: =K25*K9 | L24: =L25*L9 | M24: =M25*M9 | N24: =N25*N9 | O24: =O25*O9 | P24: =P25*P9 | ... R24: =R25*R9
E25: % of Sales | H25: =$H$24/$H$9 | I25: =+H25 | J25: =+I25 | K25: =+J25 | L25: =+K25 | M25: =+L25 | N25: =+M25 | O25: =+N25 | P25: =+O25 | ... R25: =+Q25
E26: Unlevered Free Cash Flows | I26: =SUM(I22:I24) | J26: =SUM(J22:J24) | K26: =SUM(K22:K24) | L26: =SUM(L22:L24) | M26: =SUM(M22:M24) | N26: =SUM(N22:N24) | O26: =SUM(O22:O24) | P26: =SUM(P22:P24) | ... R26: =SUM(R22:R24)
E27: Terminal Value | R27: =R26*(1+C10)/(C9-C10)
E29: PV (UFCF) | I29: =I26/(1+$C$9)^I2 | J29: =J26/(1+$C$9)^J2 | K29: =K26/(1+$C$9)^K2 | L29: =L26/(1+$C$9)^L2 | M29: =M26/(1+$C$9)^M2 | N29: =N26/(1+$C$9)^N2 | O29: =O26/(1+$C$9)^O2 | P29: =P26/(1+$C$9)^P2 | ... R29: =R26/(1+$C$9)^R2
E30: PV (TV) | R30: =R27/((1+$C$9)^R2)
E31: Enterprise Value | R31: =SUM(I29:R29)+R30
E32: (+) Net Debt | R32: =('Exhibit 2'!C24+'Exhibit 2'!C21)-'Exhibit 2'!C9
E33: Equity Value | R33: =R31-R32
E34: (/) Number of Shares (in millions) | R34: ='Exhibit 6'!D33
E35: Price per Share | R35: =R33/R34

Sheet WACC
B2: Anadarko Petroleum Corp. (APC) - Weighted Average Cost of Capital (WACC) Calculation
B4: WACC Calculation | F4: Comparable Companies
C6: Anadarko | D6: Comparables | G6: Anadarko | H6: Chevron | I6: Occidental | J6: Conoco Phillips | K6: Devon Energy | L6: Hess Corp | M6: Noble Energy
B7: MV Debt / Capital | C7: =INDEX('Exhibit 6'!D:D,MATCH("MV Leverage (%)",'Exhibit 6'!B:B,0)) | D7: =AVERAGE('Exhibit 6'!D36:J36) | F7: Debt Outstanding | G7: ='Exhibit 6'!D28 | H7: ='Exhibit 6'!E28 | I7: ='Exhibit 6'!F28 | J7: ='Exhibit 6'!G28 | K7: ='Exhibit 6'!H28 | L7: ='Exhibit 6'!I28 | M7: ='Exhibit 6'!J28
B8: MV Debt / Equity | C8: =C7/(1-C7) | D8: =D7/(1-D7) | F8: Equity (Market Value) | G8: ='Exhibit 6'!D31 | H8: ='Exhibit 6'!E31 | I8: ='Exhibit 6'!F31 | J8: ='Exhibit 6'!G31 | K8: ='Exhibit 6'!H31 | L8: ='Exhibit 6'!I31 | M8: ='Exhibit 6'!J31
B9: Asset Beta | C9: =D9 | D9: =AVERAGE(H10:M10) | F9: Equity Beta vs. S&P500 (5-Year Estimate) | G9: ='Exhibit 6'!D40 | H9: ='Exhibit 6'!E40 | I9: ='Exhibit 6'!F40 | J9: ='Exhibit 6'!G40 | K9: ='Exhibit 6'!H40 | L9: ='Exhibit 6'!I40 | M9: ='Exhibit 6'!J40
B10: Equity Beta (Assuming Constant Debt Level) | C10: =C9*(1+(1-C17)*C8) | D10: =AVERAGE(H9:M9) | F10: Asset Beta | G10: =(G8*G9+G7*(1-$C$17)*$C$16)/(G8+G7*(1-$C$17)) | H10: =(H8*H9+H7*(1-$C$17)*$C$16)/(H8+H7*(1-$C$17)) | I10: =(I8*I9+I7*(1-$C$17)*$C$16)/(I8+I7*(1-$C$17)) | J10: =(J8*J9+J7*(1-$C$17)*$C$16)/(J8+J7*(1-$C$17)) | K10: =(K8*K9+K7*(1-$C$17)*$C$16)/(K8+K7*(1-$C$17)) | L10: =(L8*L9+L7*(1-$C$17)*$C$16)/(L8+L7*(1-$C$17)) | M10: =(M8*M9+M7*(1-$C$17)*$C$16)/(M8+M7*(1-$C$17))
B11: Equity Beta (Assuming Constant Leverage Ratio) | C11: =C9*(1+C8)
F12: Equity (Book Value) | G12: ='Exhibit 6'!D29 | H12: ='Exhibit 6'!E29 | I12: ='Exhibit 6'!F29 | J12: ='Exhibit 6'!G29 | K12: ='Exhibit 6'!H29 | L12: ='Exhibit 6'!I29 | M12: ='Exhibit 6'!J29
B13: Estimated Rating | C13: BBB | F13: Enterprise Value | G13: =G12+G7 | H13: =H12+H7 | I13: =I12+I7 | J13: =J12+J7 | K13: =K12+K7 | L13: =L12+L7 | M13: =M12+M7
B14: Cost of Debt | C14: ='Exhibit 9'!M25/100 | D14: {=AVERAGE('Exhibit 9'!M8:M26/100)} | F14: EBITDAX | G14: ='Exhibit 6'!D22 | H14: ='Exhibit 6'!E22 | I14: ='Exhibit 6'!F22 | J14: ='Exhibit 6'!G22 | K14: ='Exhibit 6'!H22 | L14: ='Exhibit 6'!I22 | M14: ='Exhibit 6'!J22
F15: EV/EBITDAX | G15: =G13/G14 | H15: =H13/H14 | I15: =I13/I14 | J15: =J13/J14 | K15: =K13/K14 | L15: =L13/L14 | M15: =M13/M14
B16: Debt Beta | C16: 0.2
B17: Tax Rate | C17: 0.25 | F17: Net Income to Commmon | G17: ='Exhibit 6'!D24 | H17: ='Exhibit 6'!E24 | I17: ='Exhibit 6'!F24 | J17: ='Exhibit 6'!G24 | K17: ='Exhibit 6'!H24 | L17: ='Exhibit 6'!I24 | M17: ='Exhibit 6'!J24
B18: Market Risk Premium | C18: 0.05 | F18: P/E | G18: =IF(G8/G17>0, G8/G17, "N/A") | H18: =IF(H8/H17>0, H8/H17, "N/A") | I18: =IF(I8/I17>0, I8/I17, "N/A") | J18: =IF(J8/J17>0, J8/J17, "N/A") | K18: =IF(K8/K17>0, K8/K17, "N/A") | L18: =IF(L8/L17>0, L8/L17, "N/A") | M18: =IF(M8/M17>0, M8/M17, "N/A")
B19: Risk Free Rate (Treasury Bonds 10-Year) | C19: =INDEX('Exhibit 5'!B:B,MATCH(" 10 Years",'Exhibit 5'!A:A,0))
B21: Cost of Equity | C21: =$C19+C10*$C18 | D21: =$C19+D10*$C18
B22: WACC | C22: =C21*(1-C7)+C14*(1-$C17)*C7 | D22: =D21*(1-D7)+D14*(1-$C17)*D7

Sheet Synergies
S1: Year | T1: 2019 | U1: =T1+1 | V1: =U1+1 | W1: =V1+1 | X1: =W1+1 | Y1: =X1+1 | Z1: =Y1+1 | AA1: =Z1+1 | AB1: =AA1+1 | AC1: =AB1+1
B2: Anadarko Petroleum Corp. (APC) - Synergies Gains Analysis | S2: Period | T2: 0 | U2: =T2+1 | V2: =U2+1 | W2: =V2+1 | X2: =W2+1 | Y2: =X2+1 | Z2: =Y2+1 | AA2: =Z2+1 | AB2: =AA2+1 | AC2: =AB2+1
B4: OXY & APC - 05/05/19 Revised Proposal Synergies Gains Analysis | O4: CVX & APC - 04/11/19 Proposal Synergies Gains Analysis
B6: Premium Paid Calculation | O6: Premium Paid Calculation
B8: Stock Purchase Value Calculation | O8: Stock Purchase Value Calculation
B9: (x) Stock Exchange Ratio: OXY Shares | D9: 0.2934 | O9: (x) Stock Exchange Ratio: CVX Shares | Q9: 0.3869
B10: (x) Shares Oustanding (in millions) | D10: ='Exhibit 6'!$D$33 | O10: (x) Shares Oustanding (in millions) | Q10: ='Exhibit 6'!$D$33
B11: (x) OXY Share Price | D11: =+'Exhibit 8b'!$B$14 | O11: (x) CVX Share Price | Q11: ='Exhibit 3'!$D$14
B12: Stock Purchase Value | D12: =+D9*D10*D11 | O12: Stock Purchase Value | Q12: =+Q9*Q10*Q11
B14: Cash Purchase Value Calculation | O14: Cash Purchase Value Calculation
B15: (x) Shares Oustanding (Millions) | D15: ='Exhibit 6'!$D$33 | O15: (x) Shares Oustanding (Millions) | Q15: ='Exhibit 6'!$D$33
B16: (x) Cash Offer Share Price | D16: 59 | O16: (x) Cash Offer Share Price | Q16: 16.25
B17: Cash Purchase Value | D17: =+D15*D16 | O17: Cash Purchase Value | Q17: =Q11*Q15
B19: Total Deal Value | D19: =+D17+D12 | O19: Total Deal Value | Q19: =+Q17+Q12
B21: Unaffected Share Price | D21: ='Exhibit 8b'!$C$14 | O21: Unaffected Share Price | Q21: ='Exhibit 8b'!C7
B22: Unaffected Company Value | D22: =D21*D10 | O22: Unaffected Company Value | Q22: =Q21*Q15
B24: Premium Paid | D24: =+D19-D22 | O24: Premium Paid | Q24: =Q17-Q22
B26: Synergies Gains Case Assumptions | O26: Synergies Gains Case Assumptions
B28: Cost Savings | O28: Cost Savings
B29: Operational Cost Savings | D29: 500 | O29: Transaction Synergies | Q29: 700
B30: Supply Chain Integration Cost Savings | D30: 600 | O30: Other Efficiencies Savings | Q30: 300
B31: G&A Reduction Savings | D31: 900 | O31: CapEx Spending Reduction Savings | Q31: 1000
B32: CapEx Spending Reduction Savings | D32: 1000
B34: Valuation | O34: Valuation
B35: Effective Tax Rate | D35: 0.25 | O35: Effective Tax Rate | Q35: 0.25
B36: WACC | D36: =WACC!$C$22 | O36: WACC | Q36: =WACC!C22
B37: Terminal Value Growth Rate | D37: =DCF!C10 | O37: Terminal Value Growth Rate | Q37: =DCF!C10
B39: Synergies Gains Analysis | O39: Synergies Gains Analysis
B40: ($ in millions) | D40: =TEXT(T$1,"#")&"E" | E40: =TEXT(U$1,"#")&"P" | F40: =TEXT(V$1,"#")&"P" | G40: =TEXT(W$1,"#")&"P" | H40: =TEXT(X$1,"#")&"P" | I40: =TEXT(Y$1,"#")&"P" | J40: =TEXT(Z$1,"#")&"P" | K40: =TEXT(AA$1,"#")&"P" | L40: =TEXT(AB$1,"#")&"P" | M40: =TEXT(AC$1,"#")&"P" | O40: ($ in millions) | Q40: =TEXT(T$1,"#")&"E" | R40: =TEXT(U$1,"#")&"P" | S40: =TEXT(V$1,"#")&"P" | T40: =TEXT(W$1,"#")&"P" | U40: =TEXT(X$1,"#")&"P" | V40: =TEXT(Y$1,"#")&"P" | W40: =TEXT(Z$1,"#")&"P" | X40: =TEXT(AA$1,"#")&"P" | Y40: =TEXT(AB$1,"#")&"P" | Z40: =TEXT(AC$1,"#")&"P"
B41: Operational Cost Savings | D41: =D42*$D$29 | E41: =E42*$D$29 | F41: =F42*$D$29 | G41: =G42*$D$29 | H41: =H42*$D$29 | I41: =I42*$D$29 | J41: =J42*$D$29 | K41: =K42*$D$29 | ... M41: =M42*$D$29 | O41: Transaction Synergies | Q41: =+Q42*$Q$29 | R41: =+R42*$Q$29 | S41: =+S42*$Q$29 | T41: =+T42*$Q$29 | U41: =+U42*$Q$29 | V41: =+V42*$Q$29 | W41: =+W42*$Q$29 | X41: =+X42*$Q$29 | ... Z41: =+Z42*$Q$29
B42: % of Expected Total Annual Cost Savings Realized | D42: 0 | E42: 0.2 | F42: 0.4 | G42: 0.6 | H42: 0.8 | I42: 1 | J42: =I42 | K42: =J42 | L42: =K42 | M42: =L42 | O42: % of Expected Total Annual Cost Savings Realized | Q42: 0 | R42: 0.2 | S42: 0.4 | T42: 0.6 | U42: 0.8 | V42: 1 | W42: =V42 | X42: =W42 | Y42: =X42 | Z42: =Y42
B44: Supply Chain Integration Cost Savings | D44: =$D$30*D45 | E44: =$D$30*E45 | F44: =$D$30*F45 | G44: =$D$30*G45 | H44: =$D$30*H45 | I44: =$D$30*I45 | J44: =$D$30*J45 | K44: =$D$30*K45 | ... M44: =$D$30*M45 | O44: Other Efficiencies Savings | Q44: =+Q45*$Q$30 | R44: =+R45*$Q$30 | S44: =+S45*$Q$30 | T44: =+T45*$Q$30 | U44: =+U45*$Q$30 | V44: =+V45*$Q$30 | W44: =+W45*$Q$30 | X44: =+X45*$Q$30 | ... Z44: =+Z45*$Q$30
B45: % of Expected Total Annual Cost Savings Realized | D45: 0 | E45: 0.2 | F45: 0.4 | G45: 0.6 | H45: 0.8 | I45: 1 | J45: =I45 | K45: =J45 | L45: =K45 | M45: =L45 | O45: % of Expected Total Annual Cost Savings Realized | Q45: 0 | R45: 0.2 | S45: 0.4 | T45: 0.6 | U45: 0.8 | V45: 1 | W45: =V45 | X45: =W45 | Y45: =X45 | Z45: =Y45
B47: G&A Reduction | D47: =D48*$D$31 | E47: =E48*$D$31 | F47: =F48*$D$31 | G47: =G48*$D$31 | H47: =H48*$D$31 | I47: =I48*$D$31 | J47: =J48*$D$31 | K47: =K48*$D$31 | ... M47: =M48*$D$31 | O47: CapEx Spending Reduction | Q47: =+Q48*$Q$31 | R47: =+R48*$Q$31 | S47: =+S48*$Q$31 | T47: =+T48*$Q$31 | U47: =+U48*$Q$31 | V47: =+V48*$Q$31 | W47: =+W48*$Q$31 | X47: =+X48*$Q$31 | ... Z47: =+Z48*$Q$31
B48: % of Expected Total Annual Cost Savings Realized | D48: 0 | E48: 0.2 | F48: 0.4 | G48: 0.6 | H48: 0.8 | I48: 1 | J48: =I48 | K48: =J48 | L48: =K48 | M48: =L48 | O48: % of Expected Total Annual Cost Savings Realized | Q48: 0.3 | R48: 1 | S48: =R48 | T48: =S48 | U48: =T48 | V48: =U48 | W48: =V48 | X48: =W48 | Y48: =X48 | Z48: =Y48
B50: CapEx Spending Reduction | D50: =D51*$D$32 | E50: =E51*$D$32 | F50: =F51*$D$32 | G50: =G51*$D$32 | H50: =H51*$D$32 | I50: =I51*$D$32 | J50: =J51*$D$32 | K50: =K51*$D$32 | ... M50: =M51*$D$32 | O50: Pre-tax Cash Flow | Q50: =+SUM(Q41,Q44,Q47) | R50: =+SUM(R41,R44,R47) | S50: =+SUM(S41,S44,S47) | T50: =+SUM(T41,T44,T47) | U50: =+SUM(U41,U44,U47) | V50: =+SUM(V41,V44,V47) | W50: =+SUM(W41,W44,W47) | X50: =+SUM(X41,X44,X47) | ... Z50: =+SUM(Z41,Z44,Z47)
B51: % of Expected Total Annual Cost Savings Realized | D51: 0.3 | E51: 1 | F51: =E51 | G51: =F51 | H51: =G51 | I51: =H51 | J51: =I51 | K51: =J51 | L51: =K51 | M51: =L51 | O51: After-Tax Cash Flow | Q51: =+Q50*(1-$Q$35) | R51: =+R50*(1-$Q$35) | S51: =+S50*(1-$Q$35) | T51: =+T50*(1-$Q$35) | U51: =+U50*(1-$Q$35) | V51: =+V50*(1-$Q$35) | W51: =+W50*(1-$Q$35) | X51: =+X50*(1-$Q$35) | ... Z51: =+Z50*(1-$Q$35)
O52: Terminal Value | Z52: =(Z51*(1+Q37)/(Q36-Q37))
B53: Pre-tax Cash Flow | D53: =SUM(D41,D44,D47,D50) | E53: =SUM(E41,E44,E47,E50) | F53: =SUM(F41,F44,F47,F50) | G53: =SUM(G41,G44,G47,G50) | H53: =SUM(H41,H44,H47,H50) | I53: =SUM(I41,I44,I47,I50) | J53: =SUM(J41,J44,J47,J50) | K53: =SUM(K41,K44,K47,K50) | ... M53: =SUM(M41,M44,M47,M50) | O53: Total After-Tax Cash Flow | Q53: =+Q51+Q52 | R53: =+R51+R52 | S53: =+S51+S52 | T53: =+T51+T52 | U53: =+U51+U52 | V53: =+V51+V52 | W53: =+W51+W52 | X53: =+X51+X52 | ... Z53: =+Z51+Z52
B54: After-Tax Cash Flow | D54: =D53*(1-$D$35) | E54: =E53*(1-$D$35) | F54: =F53*(1-$D$35) | G54: =G53*(1-$D$35) | H54: =H53*(1-$D$35) | I54: =I53*(1-$D$35) | J54: =J53*(1-$D$35) | K54: =K53*(1-$D$35) | ... M54: =M53*(1-$D$35)
...

Sheet Merger Model
B2: Anadarko Petroleum Corp. (APC) - Merger Model
B4: OXY & APC | G4: CVX & APC
B6: May 5th | G6: April 11th
B7: ($ in millions) | G7: ($ in millions)
B9: Stock Exchange Ratio: OXY Shares | C9: 0.2934 | G9: Stock Exchange Ratio: CVX shares | H9: 0.3869
B10: Cash Per Share | C10: 59 | G10: Cash Per Share | H10: 16.25
B11: APC Shares Outstanding (in millions) | C11: ='Exhibit 6'!$D$33 | G11: APC Shares Outstanding (Million) | H11: ='Exhibit 6'!$D$33
C13: Occidental | D13: Anadarko | E13: NewCo | H13: Chevron | I13: Anadarko | J13: NewCo
B14: Stock Price | C14: =+'Exhibit 8b'!B14 | D14: =+'Exhibit 8b'!C14 | G14: Stock Price | H14: ='Exhibit 8b'!D7 | I14: ='Exhibit 8b'!C7
B15: Number of OXY Shares (Million) | C15: =+'Exhibit 6'!F33 | D15: =+C9*C11 | E15: =C15+D15 | G15: Number of CVX Shares (Million) | H15: ='Exhibit 6'!E33 | I15: =H9*'Exhibit 6'!D33 | J15: =H15+I15
B16: Fraction Ownership in NewCo | C16: =+C15/$E$15 | D16: =+D15/$E$15 | G16: Fraction Ownership in NewCo | H16: =H15/J15 | I16: =I15/J15
B18: Standalone Market Value Equity Value | C18: =C15*C14 | D18: =D14*C11 | E18: =C18+D18 | G18: Standalone Equity Value | H18: =H14*H15 | I18: =I14*H11 | J18: =H18+I18
B20: Offer Price | D20: =(D15*C14)+(C10*C11) | G20: Offer Price | I20: =(I15*H14)+(H10*H11)
B21: Premium Paid in $ | D21: =D20-D18 | E21: =C21+D21 | G21: Premium Paid in $ | I21: =I20-I18 | J21: =H21+I21
B23: Synergies | D23: =Synergies!D60 | E23: =+D23+C23 | G23: Synergies | I23: =+Synergies!Q57 | J23: =I23
B25: Break-up Fees | D25: 1000 | E25: =+D25+C25
B26: Transaction Costs | D26: =+D27*D18 | E26: =+D26+C26 | G26: Transaction Costs | I26: =+D27*I18 | J26: =I26
B27: % of Equity Value | D27: 0.02 | G27: % of Equity Value | I27: 0.02
B29: Value of NewCo equity | C29: =E29*C16 | D29: =E29*D16 | E29: =+E18+E23-E25-E26 | G29: Value of NewCo equity | H29: =J29*H16 | I29: =J29*I16 | J29: =J18+J23-J26
B30: NewCo Stock-Price | E30: =E29/E15 | G30: NewCo Stock-Price | J30: =J29/J15
B31: Net Gain in $ | C31: =C29-C18 | D31: =D29+C10*C11-D18 | E31: =C31+D31 | G31: Net Gain in $ | H31: =H29-H18 | I31: =I29-I18 | J31: =H31+I31
B32: Net Gain in % | C32: =C31/C18 | D32: =D31/D18 | G32: Net Gain in % | H32: =H31/H18 | I32: =I31/I18
B34: April 24th
B35: ($ in millions)
B37: Stock Exchange Ratio: OXY Shares | C37: 0.6094
B38: Cash Per Share | C38: 38
B39: APC Shares Outstanding (in millions) | C39: ='Exhibit 6'!$D$33
C41: Occidental | D41: Anadarko | E41: NewCo
B42: Stock Price | C42: ='Exhibit 8b'!$B$14 | D42: ='Exhibit 8b'!$C$14
B43: Number of OXY Shares (in millions) | C43: ='Exhibit 6'!F33 | D43: =+C39*C37 | E43: =C43+D43
B44: Fraction Ownership in NewCo | C44: =+C43/$E$43 | D44: =+D43/$E$43
B46: Standalone Equity Value | C46: =C43*C42 | D46: =D42*C39 | E46: =C46+D46
B48: Offer Price | D48: =(D43*C42)+(C38*C39)
B49: Premium Paid in $ | D49: =D48-D46 | E49: =C49+D49
B51: Synergies | D51: =+D23 | E51: =C51+D51
B53: Break-up Fees | D53: 1000 | E53: =C53+D53
B54: Transaction Costs | D54: =+D55*D46 | E54: =C54+D54
B55: % of Equity Value | D55: 0.02
B57: Value of NewCo equity | C57: =E57*C44 | D57: =E57*D44 | E57: =E46+E51-E53-E54
B58: NewCo Stock-Price | E58: =E57/E43
...

Sheet Berk-Hath Investment Package
B2: Anadarko Petroleum Corp. (APC) - Berkshire-Hathaway Investment Package
B4: Funding Package Analysis | E4: Investment Package - Senstivity Analysis
B6: Preferred Stock | E6: Sensitivity Analysis (Total Present Value in millions)
B7: ($ in millions) | E7: Step | F7: 0.005
G8: Discount Rate
B9: Preferred Shares Outstanding | C9: 100000 | F9: =C44 | G9: =H9-$F$7 | H9: =I9-$F$7 | I9: 0.073 | J9: =I9+$F$7 | K9: =J9+$F$7
B10: Issue Price Per Preferred Share | C10: 0.1 | E10: Dividend Rate | F10: =F11-$F$7 | H10: 11137.088 | I10: 10775.675 | J10: 10430.581 | K10: 10100.965
B11: Total Face Value of Preferred Stock | C11: =C9*C10 | F11: =F12-$F$7 | G11: 11152.883 | H11: 10782.639 | I11: 10429.314 | J11: 10092.029 | K11: 9769.9543
B12: Annual Dividend Rate | C12: 0.08 | F12: =C12 | G12: 11152.883 | H12: 10782.639 | I12: 10429.314 | J12: 10092.029 | K12: 9769.9543
B13: Dividend Payments Per Year | C13: 4 | F13: =F12+$F$7 | G13: 11515.713 | H13: 11137.088 | I13: 10775.675 | J13: 10430.581 | K13: 10100.965
B14: Redemption Term (Years) | C14: 10 | F14: =F13+$F$7 | G14: 12241.373 | H14: 11845.986 | I14: 11468.395 | J14: 11107.684 | K14: 10762.988
B15: Discount Rate | C15: ='Exhibit 9'!M25/100
B16: Redemption Terms | C16: 1.05 | G16: Discount Rate
B17: Redemption Value | C17: =C16*C11 | F17: =C44 | G17: =H17-$F$7 | H17: =I17-$F$7 | I17: 0.073 | J17: =I17+$F$7 | K17: =J17+$F$7
E18: Term | F18: =F19-1 | H18: 11753.87 | I18: 11434.067 | J18: 11126.314 | K18: 10830.086
B19: PV of Dividend Payments | C19: =PV(C15, C14, -C12*C11) | F19: =F20-1 | G19: 12166.19 | H19: 11801.442 | I19: 11451.836 | J19: 11116.65 | K19: 10795.2
B20: PV of Redemption Payment | C20: =PV(C15, C14, 0, -C17) | F20: 10 | G20: 12241.373 | H20: 11845.986 | I20: 11468.395 | J20: 11107.684 | K20: 10762.988
F21: =F20+1 | G21: 12312.099 | H21: 11887.693 | I21: 11483.828 | J21: 11099.368 | K21: 10733.244
B22: Total Present Value of Preferred Stock | C22: =SUM(C19:C20) | F22: =F21+1 | G22: 12378.634 | H22: 11926.745 | I22: 11498.211 | J22: 11091.653 | K22: 10705.78
B24: Equity Warrant | G24: Volatility
B25: ($ in millions except share price) | F25: =C44 | G25: =H25-2% | H25: =I25-2% | I25: 0.24 | J25: =I25+2% | K25: =J25+2%
E26: Share Price | F26: =F27-5 | H26: 11101.21 | I26: 11168.767 | J26: 11236.951 | K26: 11305.388
B27: Number of Shares Issued | C27: 82000000 | F27: =F28-5 | G27: 11144.535 | H27: 11219.242 | I27: 11294.311 | J27: 11369.393 | K27: 11444.217
F28: 61.38 | G28: 11268.919 | H28: 11350.67 | I28: 11432.167 | J28: 11513.182 | K28: 11593.534
B29: Risk-Free Rate | C29: ='Exhibit 5'!B10 | F29: =F28+5 | G29: 11406.866 | H29: 11494.415 | I29: 11581.265 | J29: 11667.278 | K29: 11752.334
B30: Time to Maturity (Years) | C30: 10 | F30: =F29+5 | G30: 11557.274 | H30: 11649.411 | I30: 11740.588 | J30: 11830.715 | K30: 11919.706
B31: Current Stock Price | C31: ='Exhibit 6'!F32
B32: Dividend Yield | C32: 0.044
B33: Strike Price | C33: 62.5
B34: Volatility | C34: 0.24
B36: d1 | C36: =(LN(C31/C33)+(C29-C32+0.5*C34^2)*C30)/(C34*SQRT(C30))
B37: d2 | C37: =C36-C34*SQRT(C30)
B38: N(d1) | C38: =NORMSDIST(C36)
B39: N(d2) | C39: =NORMSDIST(C37)
B41: B-S Call Value | C41: =C31*EXP(-C32*C30)*C38-C33*EXP(-C29*C30)*C39
B42: Total Value of Equity Warrant | C42: =C41*C27/1000000
B44: Total Value of Package | C44: =C42+C22

Sheet Raw Data >>>

Sheet Exhibit 1
A1: Exhibit 1 Anadarko Income Statements ($ millions)
B4: Year ending Dec. 31st
B5: 2017 | C5: 2018
A8: E&P Revenue | B8: 9381 | C8: 11482
A9: Other revenue, net | B9: 2527 | C9: 1900
A10: Total revenue, net | B10: 11908 | C10: 13382
A11: Costs and expenses
A12: Oil and gas operating | B12: 988 | C12: 1153
A13: Oil and gas transportation | B13: 914 | C13: 878
A14: Exploration | B14: 2535 | C14: 459
A15: Gathering, processing, and marketing | B15: 1552 | C15: 1047
A16: General and administrative | B16: 994 | C16: 1084
A17: Depreciation, depletion, and amortization | B17: 4279 | C17: 4254
A18: Production, property, and other taxes | B18: 582 | C18: 826
A19: Other expenses | B19: 629 | C19: 1062
A20: Total costs and expenses | B20: 12473 | C20: 10763
A21: Operating income (loss) | B21: -565 | C21: 2619
A22: Interest expense and other, net | B22: 1123 | C22: 1134
A23: Income tax (benefit) | B23: -1477 | C23: 733
... A26: Net income (loss) to common shareholders | B26: -456 | C26: 615
A29: Source: Anadarko Petroleum Corporation 10-K filed on February 14, 2019.

Sheet Exhibit 2
A1: Exhibit 2 Anadarko Balance Sheets ($ millions)
B4: As of Dec. 31st
B5: 2017 | C5: 2018
A8: Assets
A9: Cash and cash equivalents | B9: 4553 | C9: 1295
A10: Accounts receivable | B10: 1829 | C10: 2026
A11: Inventory | B11: 316 | C11: 235
A12: Other current assets | B12: 64 | C12: 239
A13: Total current assets | B13: 6762 | C13: 3795
A14: Net property and equipment | B14: 27451 | C14: 28615
A15: Goodwill and intangibles | B15: 5662 | C15: 5630
A16: Other assets | B16: 2211 | C16: 2336
A17: Total assets | B17: 42086 | C17: 40376
A19: Liabilities and equity
A20: Accounts payable | B20: 2160 | C20: 2164
A21: Short-term debt | B21: 142 | C21: 947
A22: Other current liabilities | B22: 1604 | C22: 1547
A23: Total current liabilities | B23: 3906 | C23: 4658
A24: Long-term debt | B24: 15547 | C24: 15470
A25: Other long-term liabilities | B25: 8843 | C25: 9305
A26: Equity
A27: Noncontrolling interests | B27: 3094 | C27: 2447
A28: Common stockholders | B28: 10696 | C28: 8496
A29: Total liabilities and equity | B29: 42086 | C29: 40376
A32: Source: Anadarko Petroleum Corporation 10-K filed on February 14, 2019.

Sheet Exhibit 3
A1: Exhibit 3 Timeline of Merger Proposals
C4: Stated Offer per Share from
A5: Date | B5: Description | C5: Occidental | D5: Chevron | F5: Consideration
A8: 43004 | B8: Private Discussion | C8: 61.22 | F8: 100% OXY shares
A9: 43119 | B9: Private Discussion | C9: 76 | F9: Not more than 50% cash
A10: 43502 | B10: Private Discussion | D10: 64 | F10: 25% cash and 75% CVX shares
A11: 43544 | B11: Private Discussion | D11: 65 | F11: 25% cash and 75% CVX shares
A12: 43547 | B12: Private Discussion | C12: 76 | F12: $19 cash + 0.8737 OXY shares
A13: 43563 | B13: Private Discussion | C13: 72 | F13: 40% cash and 60% OXY shares
A14: 43566 | B14: Merger Agreement | D14: 65 | F14: $16.25 cash + 0.3869 CVX shares
A15: 43579 | B15: Public Announcement | C15: 76 | F15: $38 cash + 0.6094 OXY shares
A16: 43590 | B16: Revised Proposal | C16: 76 | F16: $59 cash + 0.2934 OXY shares
A19: Source: Anadarko Petroleum Corporation Schedule 14A filed on July 11, 2019, pp. 41-54.

Sheet Exhibit 4a
A1: Exhibit 4a Anadarko Management Projections ($ millions, unless stated otherwise)
C4: 2018 | D4: 2019 | E4: 2020 | F4: 2021 | G4: 2022 | H4: 2023 | I4: 2024 | J4: 2025 | K4: 2026 | L4: 2027 | M4: 2028
A7: Revenue | D7: 12380.95 | E7: 13150.497 | F7: 13778.208 | G7: 14880.857 | H7: 15901.161 | I7: 17747.853 | J7: 19578.203 | K7: 19969.077 | L7: 20372.041 | M7: 20775.004
A8: EBITDAX [1] | D8: 7691 | E8: 8641 | F8: 9023 | G8: 9945 | H8: 10538 | I8: 11687 | J8: 12874 | K8: 13131 | L8: 13394 | M8: 13662
A9: Capital Expenditures | D9: 6042 | E9: 5781 | F9: 6048 | G9: 6366 | H9: 5806 | I9: 5371 | J9: 5260 | K9: 5365 | L9: 5473 | M9: 5582
A10: Depreciation | D10: 4280.625 | E10: 4504.125 | F10: 4691.6719 | G10: 4884.6562 | H10: 5093.9473 | I10: 5209.1152 | J10: 5243.7468 | K10: 5349 | L10: 5456 | M10: 5565
A13: Source: Adapted from Anadarko Petroleum Corporation Schedule 14A filed on July 11, 2019 and casewriter estimates.
A14: Notes: [1] Earnings before interest, taxes, depreciation, amortization, and exploration expense.

Sheet Exhibit 5
A1: Exhibit 5 Treasury Yields and Expected Inflation on May 3, 2019 (annual rate)
B4: Treasury | C4: Expected
B5: Yields | C5: Inflation
A8: 1 Year | B8: 0.0241 | C8: 0.0219
A9: 5 Years | B9: 0.0233 | C9: 0.0176
A10: 10 Years | B10: 0.0254 | C10: 0.018
A11: 20 Years | B11: 0.0275 | C11: 0.0198
A12: 30 Years | B12: 0.0293 | C12: 0.0212
A15: Source: Source: U.S. Department of the Treasury (https://www.treasury.gov/resource-center/data-chart-center/interest-rates/pages/textview.aspx?data=yield), accessed Nov. 16, 2019.
A16: Federal Reserve Bank of Cleveland (https://www.clevelandfed.org/our-research/indicators-and-data/inflation-expectations.aspx), accessed Feb. 10, 2020.

Sheet Exhibit 6
A1: Exhibit 6 Oil & Gas Company Operating and Financial Performance ($ millions, unless stated otherwise; Dec. 31. 2018)
G4: Selected E&P Companies
D5: Anadarko | E5: Chevron | F5: Occidental | G5: ConocoPhillips | H5: Devon Energy | I5: Hess Corp | J5: Noble Energy
A7: Operating Statistics (12/31/2018)
B8: Total Proved Reserves (MMboe) | D8: 1491.8326 | E8: 12233.513 | F8: 2774.9534 | G8: 5332.4147 | H8: 833.65399 | I8: 1201.8951 | J8: 1969.581
C9: Proved Reserves, Oil (MMbbl) | D9: 667 | E9: 6017 | F9: 1583 | G9: 2847 | H9: 296 | I9: 714 | J9: 457
C10: Proved Reserves NGL (MMbbl) | D10: 268 | E10: 773 | F10: 486 | G10: 391 | H10: 227 | I10: 175 | J10: 266
C11: Proved Reserves Gas (bcf) | D11: 3230 | E11: 31576 | F11: 4095 | G11: 12149 | H11: 1802 | I11: 1815 | J11: 7231
C12: Percent Oil and NGL | D12: 0.62674591 | E12: 0.55503272 | F12: 0.7455981 | G12: 0.60722959 | H12: 0.6273586 | I12: 0.73966521 | J12: 0.36708315
C13: Percent Natural Gas | D13: 0.37325409 | E13: 0.44496728 | F13: 0.2544019 | G13: 0.39277041 | H13: 0.3726414 | I13: 0.26033479 | J13: 0.63291685
B14: Number of Employees | D14: 4700 | E14: 48600 | F14: 11000 | G14: 10800 | H14: 2900 | I14: 1708 | J14: 2330
B15: Oil Equivalent Production (MMboe) [1] | D15: 242 | E15: 1069.5 | F15: 240 | G15: 468.4 | H15: 195 | I15: 101 | J15: 353
B16: Production Cost per BOE ($) | D16: 4.73 | E16: 10.78 | F16: 11.52 | G16: 13.63 | H16: 8.22 | I16: 15.73 | J16: 10.76
A18: Financial Statistics (12/31/2018)
B19: Total Revenues [2] | D19: 13382 | E19: 158902 | F19: 17824 | G19: 37491 | H19: 8648 | I19: 6152 | J19: 4814
B20: E&P Revenues | D20: 11482 | E20: 60713 | F20: 10441 | G20: 37491 | H20: 8648 | I20: 6152 | J20: 4481
B21: Exploration Costs | D21: 459 | E21: 1194 | F21: 282 | G21: 997 | H21: 679 | I21: 442 | J21: 153
B22: EBITDAX [3] | D22: 7332 | E22: 34835 | F22: 9376 | G22: 16689 | H22: 3527 | I22: 3131 | J22: 2844
B23: EBITDA | D23: 6873 | E23: 33641 | F23: 9094 | G23: 15692 | H23: 2848 | I23: 2689 | J23: 2691
B24: Net Income to Common | D24: 615 | E24: 14824 | F24: 4131 | G24: 6257 | H24: 546 | I24: -282 | J24: -66
B25: Expected EBITDA Growth (2018 - 2021) | D25: 0.083 | E25: 0.051 | F25: -0.018 | G25: 0.01 | H25: -0.014 | I25: 0.106 | J25: 0.154
B27: Assets | D27: 40376 | E27: 253863 | F27: 43854 | G27: 69980 | H27: 19566 | I27: 21433 | J27: 21010
B28: Debt Outstanding | D28: 16417 | E28: 34459 | F28: 10317 | G28: 14968 | H28: 5947 | I28: 6674 | J28: 6615
B29: Equity (book value) | D29: 10943 | E29: 155642 | F29: 21330 | G29: 32064 | H29: 9186 | I29: 10888 | J29: 10484
B31: Equity (market value) | D31: 22108.512 | E31: 207875.93 | F31: 46341.9 | G31: 71777.32 | H31: 10553.228 | I31: 11996.1 | J31: 8942.892
B32: Stock Price ($, 12/31/2018) | D32: 43.84 | E32: 108.79 | F32: 61.38 | G32: 62.35 | H32: 22.54 | I32: 40.5 | J32: 18.76
... B36: MV Leverage (%) | D36: 0.42613321 | E36: 0.14219576 | F36: 0.18208966 | G36: 0.1725511 | H36: 0.36041926 | I36: 0.35746997 | J36: 0.42518614
B37: S&P Credit Rating | D37: BBB | E37: AA | F37: A | G37: A | H37: BBB- | I37: BBB- | J37: BBB
B39: Equity Beta (vs. S&P 500)
B40: Five Year Estimate | D40: 1.5752 | E40: 1.054 | F40: 0.8762 | G40: 1.1589 | H40: 2.2218 | I40: 1.725 | J40: 1.2929
B41: 5-Year Avg MV Leverage (%) | D41: 0.34669553 | E41: 0.16503572 | F41: 0.14657168 | G41: 0.26329271 | H41: 0.35364076 | I41: 0.2880226 | J41: 0.32904699
A44: Source: Adapted from data obtained from Capital IQ, accessed March 17, 2020, CRSP, IBES, and casewriter estimates.
A45: Note: [1] Millions of Barrels of Oil Equivalent (MMBOE) includes natural gas and natural gas liquids.
A46: [2] Total revenues include both E&P revenue as well as retail and other downstream revenues.
A47: [3] Earnings before interest, taxes, depreciation, amortization, and exploration expense.

Sheet Exhibit 7
A1: Exhibit 7 Selected Energy Industry Transactions with Value Greater than $5 Billion
D4: Forward Multiple [1]
A5: Date | B5: Target | C5: Acquirer | D5: (TEV / EBITDAX)
A8: 43405 | B8: Newfield Exploration Company | C8: Encana Oil & Gas (USA) Inc. | D8: 5
A9: 43326 | B9: Energen Corporation | C9: Diamondback Energy, Inc. | D9: 8.9
A10: 43187 | B10: RSP Permian, Inc. | C10: Concho Resources Inc. | D10: 10
A11: 42905 | B11: Rice Energy Inc. | C11: EQT Corporation | D11: 7.9
A12: 42102 | B12: BG Group plc | C12: Royal Dutch Shell plc | D12: 13
A13: 41988 | B13: Talisman Energy, Inc. | C13: Repsol Oil & Gas Canada Inc. | D13: 4.7
A14: 41911 | B14: Athlon Energy, Inc. | C14: Encana Corporation | D14: 15.6
A15: 41248 | B15: Plains Exploration & Production Company | C15: Freeport-McMoRan Copper & Gold Inc. | D15: 6.7
A16: 41113 | B16: Nexen Inc. | C16: CNOOC Limited | D16: 4.3
A17: 40738 | B17: Petrohawk Energy Corporation | C17: BHP Billiton Group | D17: 10.5
A18: 40161 | B18: XTO Energy Inc. | C18: ExxonMobile Corporation | D18: 6
A19: 39988 | B19: Addax Petroleum Corporation | C19: Sinopec Group Company | D19: 5.5
... A30: 36619 | B30: Union Pacific Resources Group Inc. | C30: Anadarko Petroleum Corporation | D30: 4.9
A32: Mean | D32: 7.0173913
A33: Median | D33: 6
A36: Source: Anadarko Petroleum Corporation Schedule 14A dated July 11, 2019, pp. 62-63.
A38: Note: [1] TEV is total enterprise value and EBITDAX is earnings before interest, taxes, depreciation, amortization, and exploration expense.

Sheet Exhibit 8b
A1: Exhibit 8b Stock Prices: April 11, 2019 - May 3, 2019 ($ per share)
B4: Occidental | C4: Anadarko | D4: Chevron | E4: SP500 | G4: Event
A7: 43566 | B7: 67.18 | C7: 46.799999 | D7: 125.99 | E7: 2888.32 | G7: CVX-APC signed merger agreement
A8: 43567 | B8: 65.330002 | C8: 61.779999 | D8: 119.76 | E8: 2907.41 | G8: CVX-APC announced merger
A9: 43570 | B9: 63.360001 | C9: 62.259998 | D9: 120.14 | E9: 2905.58
A10: 43571 | B10: 63.669998 | C10: 63.599998 | D10: 121.17 | E10: 2907.06
A11: 43572 | B11: 62.650002 | C11: 64.029999 | D11: 120.27 | E11: 2900.45
A12: 43573 | B12: 61.82 | C12: 64.18 | D12: 119.86 | E12: 2905.03
A13: 43577 | B13: 63.049999 | C13: 64.059998 | D13: 121.9 | E13: 2907.97
A14: 43578 | B14: 62.360001 | C14: 63.990002 | D14: 122.02 | E14: 2933.68 | G14: OXY contacted APC about an offer
A15: 43579 | B15: 62 | C15: 71.400002 | D15: 118.28 | E15: 2927.25 | G15: OXY announced offer for APC
A16: 43580 | B16: 61.84 | C16: 71.769997 | D16: 117.9 | E16: 2926.17
A17: 43581 | B17: 61.310001 | C17: 72.800003 | D17: 117.1 | E17: 2939.88 | G17: Bank of America contacted BH
A18: 43584 | B18: 60.130001 | C18: 72.93 | D18: 117.72 | E18: 2943.03 | G18: APC and OXY resumed negotiations
A19: 43585 | B19: 58.880001 | C19: 72.849998 | D19: 120.06 | E19: 2945.83 | G19: OXY announced BH financing
A20: 43586 | B20: 57.48 | C20: 72.370003 | D20: 117.81 | E20: 2923.73
A21: 43587 | B21: 57.349998 | C21: 71.540001 | D21: 116.38 | E21: 2917.52
A22: 43588 | B22: 57.950001 | C22: 72.720001 | D22: 117.27 | E22: 2945.64
A25: Source: Casewriter analysis based on data from the CRSP Daily Stock Price File ©2020 Center for Research in Security Prices (CRSP), The University of Chicago Booth School of Business, accessed 6/23/21.

Sheet Exhibit 9
A1: Exhibit 9 Recent U.S. Oil and Gas Preferred Stock Issues
F4: At Time of Issue | L4: As of May 3, 2019
A5: Date | B5: Issuer | C5: Amount ($mm) | F5: Company Credit Rating | G5: Offering Yield (%) | H5: 10-Yr Yield | I5: Spread to 10-Yr Treasury (%) | L5: Company Credit Rating | M5: Market Yield (%)
N6: 749.82 | O6: 565.01 | P6: 142.77
N7: 96 | O7: 116.8 | P7: 22.3
A8: 43572 | B8: Energy Transfer Operating [1] | C8: 700 | E8: 1 | F8: BBB- | G8: 7.6 | H8: 2.59 | I8: 5.01 | K8: 1 | L8: BBB- | M8: 7.55 | N8: 1503 | O8: 3177 | P8: 178
A9: 43375 | B9: DCP Midstream [1] | C9: 100 | E9: 0 | F9: BB | G9: 7.95 | H9: 3.05 | I9: 4.9 | K9: 0 | L9: BB | M9: 7.44 | N9: 9.91 | O9: 9.75 | P9: 8.86
A10: 43297 | B10: Energy Transfer Operating [1] | C10: 400 | E10: 0 | F10: BB- | G10: 7.625 | H10: 2.85 | I10: 4.775 | K10: 0 | L10: BB- | M10: 7.315 | N10: 218 | O10: 35 | P10: 48
A11: 43229 | B11: DCP Midstream [1] | C11: 150 | E11: 0 | F11: BB | G11: 7.875 | H11: 3 | I11: 4.875 | K11: 0 | L11: BB | M11: 7.415
A12: 43208 | B12: Energy Transfer Operating [1] | C12: 450 | E12: 0 | F12: BB- | G12: 7.375 | H12: 2.87 | I12: 4.505 | K12: 0 | L12: BB- | M12: 7.045
A13: 43067 | B13: Andeavor Logistics | C13: 600 | E13: 1 | F13: BBB | G13: 6.875 | H13: 2.34 | I13: 4.535 | K13: 1 | L13: BBB | M13: 6.532 | N13: 3879 | O13: 9384 | P13: 891
A14: 43066 | B14: NuStar Energy [1] | C14: 150 | E14: 0 | F14: BB | G14: 9 | H14: 2.32 | I14: 6.68 | K14: 0 | L14: BB | M14: 9.22
A15: 43052 | B15: Energy Transfer Operating | C15: 950 | E15: 0 | F15: BB- | G15: 6.25 | H15: 2.4 | I15: 3.85 | K15: 1 | L15: BBB- | M15: 7.826 | N15: 3692 | O15: 3306 | P15: 692.2
A16: 43052 | B16: DCP Midstream | C16: 500 | E16: 0 | F16: BB | G16: 7.375 | H16: 2.4 | I16: 4.975 | K16: 0 | L16: BB | M16: 7.855 | N16: 2286 | O16: 978 | P16: 199.9
A17: 43052 | B17: Energy Transfer Operating | C17: 550 | E17: 0 | F17: BB- | G17: 6.625 | H17: 2.4 | I17: 4.225 | K17: 1 | L17: BBB- | M17: 7.407
A18: 43048 | B18: Summit Midstream Partners | C18: 300 | E18: 0 | F18: BB- | G18: 9.5 | H18: 2.33 | I18: 7.17 | K18: 0 | L18: BB- | M18: 13.42 | N18: 0 | O18: 825 | P18: 18.2
A19: 43012 | B19: Plains All American Pipeline | C19: 800 | E19: 1 | F19: BBB- | G19: 6.125 | H19: 2.33 | I19: 3.795 | K19: 1 | L19: BBB- | M19: 7.431 | N19: 26294 | O19: 17903 | P19: 4260
A20: 42992 | B20: EnLink Midstream Partners | C20: 400 | E20: 0 | F20: BB | G20: 6 | H20: 2.2 | I20: 3.8 | K20: 0 | L20: BB+ | M20: 10.77 | N20: 4353 | O20: 2284 | P20: 691.6
A21: 42892 | B21: NGL Energy Partners [1] | C21: 185 | E21: 0 | F21: B+ | G21: 9 | H21: 2.14 | I21: 6.86 | K21: 0 | L21: B+ | M21: 9.4 | N21: 18768 | O21: 12111 | P21: 3243.9
A22: 42850 | B22: NuStar Energy [1] | C22: 350 | E22: 0 | F22: BB+ | G22: 7.625 | H22: 2.35 | I22: 5.275 | K22: 0 | L22: BB+ | M22: 7.815 | N22: =(N20-N18)/(N21+N20-N18) | O22: =(O20-O18)/(O21+O20-O18) | P22: =(P20-P18)/(P21+P20-P18)
N23: =(N20-N18)/(#REF!+N20-N18) | O23: =(O20-O18)/(#REF!+O20-O18) | P23: =(P20-P18)/(#REF!+P20-P18)
A24: Average | N24: BBB- | O24: BBB | P24: B+
A25: Investment Grade Issuers (BBB, BBB-) | C25: 700 | G25: 6.8666667 | M25: 7.3492
A26: Non-Investment Grade Issuers (BB+, BB, BB-, B+) | C26: 373.75 | G26: 7.6833333 | M26: 8.7695 | N26: 1.23 | O26: 1.12 | P26: 1.99
A29: Source: Capital IQ.
A30: Note: [1] Market yield estimated based on spread to 10-year treasury at time of issue and 10-year treasury yield on May 3, 2019.
